Workbook

Sheet Tablero A&D
M3: SUMINISTRO, INSTALACION Y MANTENIMIENTO DE SISTEMAS CONTRA INCENDIO
A6: REPORTE DE INSPECCION, PRUEBAS Y MANTENIMIENTO A
A7: TABLERO DE ALARMA & DETECCION DIRECCIONADO
A9: CLIENTE : | F9: PARK ROYAL CANCUN
A10: ATENCION : | F10: ING. SILVESTRE CASTRO
A11: AREA : | F11: CONMUTADOR
A12: FECHA : | F12: JUNIO DEL 2026
A16: TABLERO DE ALARMA & DETECCION DIRECCIONADO | Q16: S | S16: N/A | U16: N | W16: PARAMETROS | AA16: LECTURAS | AE16: COMENTARIOS
A17: 1 | B17: CONDICIONES GENERALES
B18: ¿El tablero se encuentra en un lugar accesible?
B19: ¿Se encontro cerrado el panel?
B20: ¿La temperatura del area es adecuada?
B21: ¿El tablero esta en operación?
B22: ¿El tablero esta libre de señalizaciones de Alarma?
B23: ¿El tablero esta libre de señalizaciones de Problemas?
B24: ¿El tablero esta libre de señalizaciones de Supervision?
B25: ¿El tablero esta libre de señalizaciones de Seguridad?
B26: ¿El tablero esta libre de falla a tierra?
B27: ¿Esta habilitada la deteccion de falla a tierra?
B28: ¿Las condiciones internas del tablero son adecuadas?
A29: 2 | B29: PRUEBAS
B30: ¿El suministro de energia electrica esta regulado?
B31: ¿El suministro de energia electrica es correcto?
B32: ¿El tablero opera al desconectar la energía de C.A.?
B33: ¿EL cargador de baterías funciona correctamente?
B34: ¿Operan correctamente las baterias?
B35: ¿Las terminales en baterias se encuentran libre de sulfatacion?
B36: ¿El sistema opera en condiciones de Alarma?
B37: ¿El sistema opera en condiciones de Problema?
B38: ¿El sistema opera en condiciones de Supervision?
B39: ¿El sistema opera en condiciones de Seguridad?
B40: ¿La señal audible del tablero opera?
B41: ¿Operan correctamente las luces de señalizacion?
... B46: ¿El panel remoto opera correctamente?
A48: OBSERVACIONES :

Sheet Dispositivos A&D
L2: SUMINISTRO, INSTALACION Y MANTENIMIENTO DE SISTEMAS CONTRA INCENDIO
A6: REPORTE DE INSPECCION, PRUEBAS Y MANTENIMIENTO A
A7: DISPOSITIVOS DIRECCIONADOS DE A & D
A9: CLIENTE : | F9: =+'Tablero A&D'!F9:T9
A10: SISTEMA: | F10: NOTIFIER 2020
A11: FECHA: | F11: =+'Tablero A&D'!F12:T12
A16: DIRECCION | D16: LOOP | F16: DISPOSITIVO | N16: UBICACIÓN | W16: ALARMA | Z16: SUPERVISION | AD16: LIMPIEZA | AG16: COMENTARIOS
A38: OBSERVACIONES :

Sheet Dispositivos Convencionales
L2: SUMINISTRO, INSTALACION Y MANTENIMIENTO DE SISTEMAS CONTRA INCENDIO
A6: REPORTE DE INSPECCION, PRUEBAS Y MANTENIMIENTO A
A7: DISPOSITIVOS CONVENCIONALES DE A & D
A9: CLIENTE : | F9: =+'Dispositivos A&D'!F9:T9
A10: SISTEMA: | F10: =+'Dispositivos A&D'!F10:T10
A11: FECHA: | F11: =+'Dispositivos A&D'!F11:T11
A16: MODULO | D16: LOOP | F16: DISPOSITIVO | N16: UBICACIÓN | W16: ALARMA | Z16: SUPERVISION | AD16: LIMPIEZA | AG16: COMENTARIOS
A38: OBSERVACIONES :

Sheet Dispositivos Notificacion
L2: SUMINISTRO, INSTALACION Y MANTENIMIENTO DE SISTEMAS CONTRA INCENDIO
A6: REPORTE DE INSPECCION, PRUEBAS Y MANTENIMIENTO A
A7: DISPOSITIVOS DE NOTIFICACION DE A & D
A9: CLIENTE : | F9: =+'Dispositivos Convencionales'!F9:T9
A10: SISTEMA: | F10: =+'Dispositivos Convencionales'!F10:T10
A11: FECHA: | F11: =+'Dispositivos Convencionales'!F11:T11
A16: MODULO | D16: LOOP | F16: DISPOSITIVO | N16: UBICACIÓN | W16: ALARMA | Z16: SUPERVISION | AD16: LIMPIEZA | AG16: COMENTARIOS
A38: OBSERVACIONES :

Sheet B Jockey
M3: SUMINISTRO, INSTALACION Y MANTENIMIENTO DE SISTEMAS CONTRA INCENDIO
A6: REPORTE DE INSPECCION, PRUEBAS Y MANTENIMIENTO A
A7: BOMBA DE COMBUSTION INTERNA CONTRA INCENDIOS
A9: CLIENTE : | F9: =+'Dispositivos Notificacion'!F9:T9
A10: ATENCION : | F10: ING. LUIS SANTOS | AA10: POTENCIA : | AI10: 2 HP
A11: AREA : | F11: CUARTO DE MAQUINAS | AA11: CAPACIDAD : | AI11: 55 L/SEG
A12: FECHA : | F12: =+'Tablero A&D'!F12:T12 | AA12: VOLTAJE DE OPERACIÓN : | AI12: 440 V
A15: BOMBA JOCKEY | Q15: S | S15: N/A | U15: N | W15: PARAMETROS | AA15: LECTURAS | AE15: COMENTARIOS
A16: 1 | B16: SUCCION Y DESCARGA
A17: 1.1 | B17: ¿La valvula de succion se encuentra abierta?
A18: 1.2 | B18: ¿La valvula de succion se encuentra asegurada y/o supervisada?
A19: 1.3 | B19: ¿La valvula de descarga se encuentra abierta?
A20: 1.4 | B20: ¿La valvula de descarga se encuentra asegurada y/o supervisada?
A21: 1.5 | B21: ¿Se encuentra instalada la valvula de alivio?
A22: 1.6 | B22: ¿Se encuentra en buen estado el acoplamiento mecanico?
A23: 1.7 | B23: ¿Cuenta con las guardas el acoplamiento mecanico?
A24: 1.8 | B24: ¿Se encuentra el manometro de la linea de descarga operando?
A25: 2 | B25: TABLERO DE CONTROL
A26: 2.1 | B26: ¿Se encontro el selector en modo automatico?
A27: 2.2 | B27: ¿Funcionan los focos pilotos del tablero?
... A29: 2.4 | B29: ¿El tablero y/o sus componentes son aprobados?
A30: 2.5 | B30: ¿La linea piloto se encuentra instalada correctamente? | W30: NFPA 20
A31: 3 | B31: PRUEBAS
A32: 3.1 | B32: ¿Opera el equipo de modo manual?
A33: 3.2 | B33: ¿Opera el equipo en automatico?. | W33: Presion de Arranque:
W34: Presion de Paro:
A35: 3.3 | B35: ¿El tiempo de retardo de paro es correcto? | W35: Segundos:
A36: 3.4 | B36: ¿Se verifico el voltaje de entrada en el interruptor principal? | W36: Voltaje en fase 1:
W37: Voltaje en fase 2:
W38: Voltaje en fase 3:
A39: 3.5 | B39: ¿Se verifico el voltaje de salida en el contactor de arranque? | W39: Voltaje en fase 1:
W40: Voltaje en fase 2:
W41: Voltaje en fase 3:
A42: 3.6 | B42: ¿Se verifico la corriente de trabajo del motor? | W42: Amperes en fase 1:
W43: Amperes en fase 2:
W44: Amperes en fase 3:
A45: 3.7 | B45: ¿El motor cuenta con las RPM adecuadas?
A46: 3.8 | B46: ¿Los empaques de la bomba sellan correctamente?
A47: 3.9 | B47: ¿Existen ruidos o vibraciones anormales?
A48: 3.10 | B48: ¿Existe sobre calentamiento en carcaza de la bomba?
...

Sheet B Electrica
M3: SUMINISTRO, INSTALACION Y MANTENIMIENTO DE SISTEMAS CONTRA INCENDIO
A6: REPORTE DE INSPECCION, PRUEBAS Y MANTENIMIENTO A
A7: BOMBA DE COMBUSTION INTERNA CONTRA INCENDIOS
A9: CLIENTE : | F9: =+'B Jockey'!F9:Z9
A10: ATENCION : | F10: =+'B Jockey'!F10:T10 | AA10: POTENCIA : | AI10: 60 HP
A11: AREA : | F11: =+'B Jockey'!F11:T11 | AA11: CAPACIDAD : | AI11: 500 GPM
A12: FECHA : | F12: =+'B Jockey'!F12:T12 | AA12: VOLTAJE DE OPERACIÓN : | AI12: 440 V
A15: BOMBA ELECTRICA | Q15: S | S15: N/A | U15: N | W15: PARAMETROS | AA15: LECTURAS | AE15: COMENTARIOS
A16: 1 | B16: SUCCION Y DESCARGA
A17: 1.1 | B17: ¿La valvula de succion se encuentra abierta?
A18: 1.2 | B18: ¿La valvula de succion se encuentra asegurada y/o supervisada?
A19: 1.3 | B19: ¿La valvula de descarga se encuentra abierta?
A20: 1.4 | B20: ¿La valvula de descarga se encuentra asegurada y/o supervisada?
A21: 1.5 | B21: ¿Se encuentra instalada la valvula de alivio?
A22: 1.6 | B22: ¿Se encuentra instalada la valvula eliminadora de aire?
A23: 1.7 | B23: ¿Se encuentra en buen estado el acoplamiento mecanico?
A24: 1.8 | B24: ¿Cuenta con las guardas el acoplamiento mecanico?
A25: 1.9 | B25: ¿Se encuentra el manometro de la linea de descarga operando?
A26: 1.10 | B26: ¿Se encuentra el manovacuometro de la linea de succion operando?
A27: 1.11 | B27: ¿El nivel de aceite del cabezal de engranes es correcto?
... A33: 2.5 | B33: ¿El tablero y/o sus componentes son aprobados?
A34: 2.6 | B34: ¿La linea piloto se encuentra instalada correctamente? | W34: NFPA 20
A35: 3 | B35: PRUEBAS
A36: 3.1 | B36: ¿Opera el equipo de modo manual?
A37: 3.2 | B37: ¿Opera el mecanismo de arranque de emergencia?
A38: 3.3 | B38: ¿Opera el equipo en automatico?. | W38: Presion de Arranque:
W39: Presion de Paro:
A40: 3.4 | B40: ¿El tiempo de retardo de paro es correcto? | W40: Segundos:
A41: 3.5 | B41: ¿Se verifico el voltaje de entrada en el interruptor principal? | W41: Voltaje en fase 1:
W42: Voltaje en fase 2:
W43: Voltaje en fase 3:
A44: 3.6 | B44: ¿Se verifico el voltaje de salida en el contactor de arranque? | W44: Voltaje en fase 1:
W45: Voltaje en fase 2:
W46: Voltaje en fase 3:
A47: 3.7 | B47: ¿Se verifico la corriente de trabajo del motor? | W47: Amperes en fase 1:
W48: Amperes en fase 2:
W49: Amperes en fase 3:
A50: 3.8 | B50: ¿El motor cuenta con las RPM adecuadas?
A51: 3.9 | B51: ¿Los empaques de la bomba sellan correctamente?
A52: 3.10 | B52: ¿Existen ruidos o vibraciones anormales?
...

Sheet B Diesel
M3: SUMINISTRO, INSTALACION Y MANTENIMIENTO DE SISTEMAS CONTRA INCENDIO
A6: REPORTE DE INSPECCION, PRUEBAS Y MANTENIMIENTO A
A7: BOMBA DE COMBUSTION INTERNA CONTRA INCENDIOS
A9: CLIENTE : | F9: =+'B Electrica'!F9:Z9
A10: ATENCION : | F10: =+'B Electrica'!F10:T10 | Z10: POTENCIA : | AH10: 55 HP
A11: AREA : | F11: =+'B Electrica'!F11:T11 | Z11: CAPACIDAD : | AH11: 500 GPM
A12: FECHA : | F12: =+'B Electrica'!F12:T12 | Z12: VOLTAJE DE OPERACIÓN : | AH12: 110/12 V
A15: BOMBA COMBUSTION INTERNA DIESEL | Q15: S | S15: N/A | U15: N | W15: PARAMETROS | AA15: LECTURAS | AE15: COMENTARIOS
A16: 1 | B16: SUCCION Y DESCARGA
A17: 1.1 | B17: ¿La valvula de succion se encuentra abierta?
A18: 1.2 | B18: ¿La valvula de succion se encuentra asegurada y/o supervisada?
A19: 1.3 | B19: ¿La valvula de descarga se encuentra abierta?
A20: 1.4 | B20: ¿La valvula de descarga se encuentra asegurada y/o supervisada?
A21: 1.5 | B21: ¿Se encuentra instalada la valvula de alivio?
A22: 1.6 | B22: ¿Se encuentra instalada la valvula eliminadora de aire?
A23: 1.7 | B23: ¿Se encuentra en buen estado el acoplamiento mecanico?
A24: 1.8 | B24: ¿Cuenta con las guardas el acoplamiento mecanico?
A25: 1.9 | B25: ¿Se encuentra el manometro de la linea de descarga operando?
A26: 1.10 | B26: ¿Se encuentra el manovacuometro de la linea de succion operando?
A27: 1.11 | B27: ¿El nivel de aceite del cabezal de engranes es correcto?
... A29: 2.1 | B29: ¿Los bornes y terminales de los bancos de bateria se encuentran sin corrosion?.
A30: 2.2 | B30: ¿El cargador opera correctamente? | W30: Banco # 1:
W31: Banco # 2:
A32: 2.3 | B32: ¿El voltaje de las baterias es el correcto? | W32: Banco # 1:
W33: Banco # 2:
A34: 3 | B34: SISTEMA DE ENFRIAMIENTO
A35: 3.1 | B35: ¿Es correcto el nivel y estado del liquido anticongelante?
A36: 3.2 | B36: ¿Se encuentra libre de fugas el sistema de enfriamiento?
A37: 3.3 | B37: ¿Funciona correctamente el precalentador?
A38: 4 | B38: SISTEMA DE LUBRICACION Y COMBUSTIBLE
A39: 4.1 | B39: ¿El nivel y calidad de aceite el el correcto?.
A40: 4.2 | B40: ¿Se encuentra libre de fugas de aceite el sistema de lubricacion?
A41: 4.3 | B41: ¿El nivel del tanque de disel es el correcto? | W41: 2/3 NFPA 20
A42: 4.4 | B42: ¿Existen fugas en las lineas de alimentacion y retorno de combustible?
A43: 5 | B43: SISTEMA MOTRIZ
A44: 5.1 | B44: ¿El estado fisico de las bandas es correcto?
A45: 5.2 | B45: ¿Cuenta con guardas de proteccion las bandas?
A46: 5.3 | B46: ¿El estado fisico de las mangueras es correcto?
A47: 5.4 | B47: ¿El estado fisico de cables y conectores es correcto?
A48: 5.5 | B48: ¿Se motor cuenta con contactor de arranque manual? | W48: Banco # 1:
...

Sheet HIDRANTES
L3: SUMINISTRO, INSTALACION Y MANTENIMIENTO DE SISTEMAS CONTRA INCENDIO
A6: REPORTE DE INSPECCION, PRUEBAS Y MANTENIMIENTO A
A7: HIDRANTES
A8: CLIENTE : | F8: =+'B Diesel'!F9:Z9
A9: SISTEMA: | F9: RED DE HIDRANTES
A10: FECHA: | F10: JUNIO DEL 2026
A12: NUMERO | C12: UBICACIÓN | L12: GABINETE | O12: SEÑALAMIENTO | Q12: CALCOMANIA | R12: VALVULA ANGULAR | U12: MANGUERA | W12: CHIFLON | AA12: LLAVE DE ACOPLE | AD12: COMENTARIOS
A13: 1 | C13: SALA DE VENTAS ROYAL
A14: =+A13+1 | C14: SALIDA DE EMERGENCIA VENTAS
A15: =+A14+1 | C15: SALIDA EMERGEN P8 LADO LAGUNA
A16: =+A15+1 | C16: SALIDA EMERGEN P8 LADO MAR
A17: =+A16+1 | C17: SALIDA EMERGEN P7 LADO MAR
A18: =+A17+1 | C18: SALIDA EMERGEN P7 LADO LAGUNA
A19: 7 | C19: PASILLO HABITACION 2602
A20: 8 | C20: PASILLO HABITACION 2616
A21: 9 | C21: PASILLO HABITACION 2524
A22: 10 | C22: PASILLO HABITACION 2502
A23: 11 | C23: PASILLO HABITACION 2402
A24: 12 | C24: PASILLO HABITACION 2428
A25: 13 | C25: PASILLO HABITACION 2332
A26: 14 | C26: PASILLO HABITACION 2302
A27: 15 | C27: PASILLO HABITACION 2202
A28: 16 | C28: PASILLO HABITACION 2236
A29: 17 | C29: PASILLO HABITACION 2140
A30: 18 | C30: PASILLO HABITACION 2102
... A42: 30 | C42: COCINA ITALIANO MEXICANO
A43: 31
A44: 32
A45: 33
A46: 34
A47: 35
A48: 36
A49: 37
A50: 38
A52: OBSERVACIONES :
F109: .

Sheet EXTINTORES
L3: SUMINISTRO, INSTALACION Y MANTENIMIENTO DE SISTEMAS CONTRA INCENDIO
A6: REPORTE DE INSPECCION Y MANTENIMIENTO A
A7: EXTINTORES
A9: CLIENTE : | F9: =+HIDRANTES!F8
A10: SISTEMA: | F10: EXTINTORES PORTATILES
A11: FECHA: | F11: JUNIO DEL 2026
A13: NUMERO | C13: UBICACIÓN | L13: TIPO DE EXTINTOR | O13: CAPACIDAD | Q13: PROXIMA RECARGA | R13: PRESION | U13: ALTURA | W13: SEGURO | Y13: PINTURA | AA13: MANGUERA | AC13: DIFUSOR | AE13: SEÑALAMIENTO | AG13: OBSERVACIONES
A14: 1 | C14: FTE ELEV HUESPED SALA DE VENTAS | L14: PQS | O14: 6 KG
A15: =+A14+1 | C15: SALA DE VENTAS AREA DE VIDEOS | L15: PQS | O15: 6 KG
A16: =+A15+1 | C16: SALA DE VENTAS AREA KIDS CLUB | L16: PQS | O16: 6 KG
A17: =+A16+1 | C17: SALA DE VENTAS LADO MAR | L17: PQS | O17: 6 KG
A18: =+A17+1 | C18: SALA DE VENTAS LADO LAGUNA | L18: PQS | O18: 4.5 KG
A19: =+A18+1 | C19: ESC EMERGEN SALA DE VENTAS | L19: PQS | O19: 6 KG
A20: =+A19+1 | C20: ROPERIA PISO 8 | L20: PQS | O20: 6 KG
A21: =+A20+1 | C21: PASILLO HABITACION 2804 PISO 8 | L21: PQS | O21: 6 KG
A22: =+A21+1 | C22: PASILLO HABITACION 2706 PISO 7 | L22: PQS | O22: 6 KG
A23: =+A22+1 | C23: ROPERIA PISO 7 | L23: PQS | O23: 6 KG
A24: =+A23+1 | C24: ESC EMERGENCIA LAGUNA PISO 6 | L24: PQS | O24: 6 KG
A25: =+A24+1 | C25: PASILLO HABITACION 2608 PISO 6 | L25: PQS | O25: 4.5 KG
A26: =+A25+1 | C26: ROPERIA PISO 6 | L26: PQS | O26: 6 KG
A27: 14 | C27: SALIDA EMERGENCIA LADO MAR P 6 | L27: PQS | O27: 6 KG
A28: 15 | C28: ESC. EMERGENCIA L MAR PISO 5 | L28: PQS | O28: 6 KG
A29: 16 | C29: PASILLO HABITACION 2518 PISO 6 | L29: PQS | O29: 6 KG
A30: 17 | C30: ROPERIA PISO 5 | L30: PQS | O30: 6 KG
A31: 18 | C31: PASILLO HABITACION 2510 PISO 5 | L31: PQS | O31: 6 KG
A32: 19 | C32: ESC. EMERGENCIA L LAGUNA P-5 | L32: PQS | O32: 6 KG
A33: 20 | C33: ESC. EMERGENCIA L LAGUNA P-4 | L33: PQS | O33: 6 KG
A34: 21 | C34: PASILLO HABITACION 2406 PISO 4 | L34: PQS | O34: 6 KG
A35: 22 | C35: ROPERIA PISO 4 | L35: PQS | O35: 6 KG
A36: 23 | C36: PASILLO HABITACION 2416 PISO 4 | L36: PQS | O36: 6 KG
A37: 24 | C37: ESC. EMERGENCIA L MAR PISO 4 | L37: PQS | O37: 6 KG
A38: 25 | C38: ESC. EMERGENCIA L MAR PISO 3 | L38: PQS | O38: 6 KG
A39: 26 | C39: PASILLO HABITACION 2326 PISO 3 | L39: PQS | O39: 6 KG
A40: =+A39+1 | C40: PASILLO HABITACION 2318 PISO 3 | L40: PQS | O40: 6 KG
A41: =+A40+1 | C41: ROPERIA PISO 3 | L41: PQS | O41: 6 KG
A42: =+A41+1 | C42: PASILLO HABITACION 2310 PISO 3 | L42: PQS | O42: 6 KG
A43: =+A42+1 | C43: ESC EMERGENCIA L LAGUNA P-3 | L43: PQS | O43: 6 KG
A44: =+A43+1 | C44: ESC EMERGENCIA L LAGUNA P-2 | L44: PQS | O44: 6 KG
A45: =+A44+1 | C45: PASILLO HABITACION 2208 PISO 2 | L45: PQS | O45: 6 KG
A46: =+A45+1 | C46: PASILLO HABITACION 2216 PISO 2 | L46: PQS | O46: 6 KG
...

Sheet Ansul R-102
M3: SUMINISTRO, INSTALACION Y MANTENIMIENTO DE SISTEMAS CONTRA INCENDIO
A6: REPORTE DE INSPECCION, PRUEBAS Y MANTENIMIENTO A
A7: TABLERO DE ALARMA & DETECCION DIRECCIONADO
A9: CLIENTE : | F9: =+EXTINTORES!F9
A10: ATENCION : | F10: =+'B Diesel'!F10:T10
A11: AREA : | F11: COCINA GENERAL
A12: FECHA : | F12: =+EXTINTORES!F11
A16: SISTEMA R-102 CON CAPACIDAD DE___GALONES | Q16: S | S16: N/A | U16: N | W16: CANTIDAD | AA16: MODELO | AE16: COMENTARIOS
A17: 1 | B17: ¿ Se encuentra el Automan en un lugar accesible?
A18: 2 | B18: ¿Las condicines del liquido Ansulex son las correctas ?
A19: 3 | B19: ¿Se cuenta con tanques esclavos ?
A20: 4 | B20: ¿Los cilindros contenedores de liquido ansulex se encuentran libres de daños fisicos ?
A21: 5 | B21: ¿EL cartucho de nitrogeno (agente de expulsion) es el correcto?
A22: 6 | B22: ¿ Las boquillas en el pleno de la campana son las indicadas?
A23: 7 | B23: ¿ Las boquillas en los ductos son las indicadas ?
A24: 8 | B24: ¿ Todos los muebles se encuentran protegidos correctamente ?
A25: 9 | B25: Existen Freidoras ?
A26: 10 | B26: Existen Estufones ?
A27: 11 | B27: Existen Planchas ?
A28: 12 | B28: Existen Parrillas ?
... A32: 16 | B32: La valvula de corte de gas opera correctamente ?
A33: 17 | B33: Se realizaron pruebas de operación sin descarga de Agente Ansulex ?
A35: OBSERVACIONES :
